#Expyriment 0.8.0 (Python 2.7.10), .xpe-file, coding: cp1252
#date: Mon Oct 10 2016 15:53:59
#sha1: 243293
#modules: 
#display: size=(800, 600), window_mode=True, open_gl=2
#os: ('Windows', 'Gnolo', '8', '6.2.9200', 'AMD64', 'Intel64 Family 6 Model 60 Stepping 3, GenuineIntel')
Time,Type,Event,Value,Detail,Detail2
657,stderr,received,'Traceback (most recent call last):'
657,stderr,received,'  File "C:\\Program Files (x86)\\JetBrains\\PyCharm Community Edition 2016.2.3\\helpers\\pydev\\pydevd.py", line 1580, in <module>'
659,stderr,received,"    globals = debugger.run(setup['file'], None, None, is_module)"
659,stderr,received,'  File "C:\\Program Files (x86)\\JetBrains\\PyCharm Community Edition 2016.2.3\\helpers\\pydev\\pydevd.py", line 964, in run'
660,stderr,received,'    pydev_imports.execfile(file, globals, locals)  # execute the script'
660,stderr,received,'  File "C:/Users/Carmine Gnolo/Desktop/Code/cp-stim-pro/blog_example", line 35, in <module>'
660,stderr,received,'    print correct_response'
660,stderr,received,"NameError: name 'correct_response' is not defined"
